Workbook
Name Base: 'Data Page'!$C$94:$C$96
Name BoltColor: 'Data Page'!$M$15:$M$16
Name BoltLength: 'Data Page'!$L$35:$L$71
Name Bolts: 'Data Page'!$K$35:$K$78
Name Cees: 'Data Page'!$D$2:$D$22
Name ClipDesc: 'Data Page'!$B$112:$B$190
Name Clips: 'Data Page'!$A$112:$A$191
Name Closer: 'Data Page'!$C$86:$C$88
Name Coatings: 'Data Page'!$A$35:$A$38
Name CoatingsMinus: 'Data Page'!$M$22:$M$24
Name ColdForm: 'Data Page'!$D$35:$D$58
Name Colors: 'Data Page'!$A$2:$A$31
Name COMTRIM: 'Data Page'!$R$2:$R$403
Name DoorColor: 'Data Page'!$E$79:$E$80
Name Doors: 'Data Page'!$A$201:$A$213
Name EaveStruts: 'Data Page'!$F$35:$F$57
Name EWPANEL: 'Data Page'!$L$401:$L$416
Name FBDesc: 'Data Page'!$H$42:$H$43
Name FinTrim: 'Data Page'!$G$73:$G$74
Name FinType: 'Data Page'!$E$73:$E$76
Name FlangeBraces: 'Data Page'!$H$35:$H$38
Name Frame: 'Data Page'!$C$73:$C$74
Name FrameColor: 'Data Page'!$F$301:$F$320
Name FrameSize: 'Data Page'!$J$82:$J$84
Name Gage: 'Data Page'!$K$105:$K$106
Name GalvClipDesc: 'Data Page'!$G$113:$G$119
Name GalvClips: 'Data Page'!$F$113:$F$119
Name Glass: 'Data Page'!$A$73:$A$76
Name Handle: 'Data Page'!$M$92:$M$93
Name HotRolled: 'Data Page'!$Y$2:$Y$165
Name Locks: 'Data Page'!$G$86:$G$94
Name Louvers: 'Data Page'!$D$105:$D$111
Name MasticColor: 'Data Page'!$M$2:$M$5
Name Misc.: 'Data Page'!$C$372:$C$393
Name Misc.Color: 'Data Page'!$F$372:$F$393
Name Misc.Des: 'Data Page'!$D$372:$D$393
Name Misc.Length: 'Data Page'!$G$372:$G$393
Name Misc.Part: 'Data Page'!$E$372:$E$393
Name Misc.Part2: 'Data Page'!$I$372:$I$391
Name Mullion: 'Data Page'!$E$86:$E$87
Name PANELS: 'Data Page'!$J$401:$J$416
Name PGColor: 'Data Page'!$M$11
Name RidgeColor: 'Data Page'!$I$92:$I$93
Name RidgeFins: 'Data Page'!$K$92:$K$93
Name RidgeVents: 'Data Page'!$D$92:$D$93
Name ROOF: 'Data Page'!$L$423:$L$432
Name RoofColors: 'Data Page'!$G$2:$G$32
Name Screen: 'Data Page'!$G$105:$G$106
Name ScrewColors: 'Data Page'!$J$2:$J$30
Name ScrewLength: 'Data Page'!$AH$3:$AH$21
Name Screws: 'Data Page'!$AF$3:$AF$21
Name Skirt: 'Data Page'!$K$100:$K$101
Name SSR: 'Data Page'!$P$539:$P$542
Name SSRHDW: 'Data Page'!$F$141:$F$173
Name SSRHDWDESC: 'Data Page'!$G$141:$G$173
Name SSRSkylight: 'Data Page'!$AL$3:$AL$6
Name Swing: 'Data Page'!$G$79:$G$83
Name SWPANEL: 'Data Page'!$P$517:$P$532
Name TRIMDATA: 'Data Page'!$P$2:$Q$403
Name TRIMDESC: 'Data Page'!$Q$2:$Q$403

Sheet Cover
I1: Interplant Load Date:
I2: Load Date:
I3: On Site Date:
J22: Total number of shipper pages: (not including cover page) | M22: 10
E24: Job Number: | G24: 403184_Secondary
D26: CHANGE ORDER #:
E27: Issue Date: | G27: 45985
E28: Customer:
E29: Job Name:
D30: Job Site Location:
E32: Building Size:
E33: Total Weight:
B34: SPECIAL NOTES:
K36: DRAWN BY:
K37: CHECKER:

Sheet Eave Struts
I1: SHIPPER NUMBER | K1: 1 | M1: OF | N1: =Cover!$M$22 -> 10
G2: JOB NUMBER | I2: =Cover!$G$24 -> 403184_Secondary | K2: ISSUE DATE | M2: =Cover!$G$27 -> 45985
G3: BUILDING NUMBER | K3: REVISION NUMBER
G4: DRAWN BY | I4: =Cover!$M$36 | K4: REVISION BY
G5: CHECKED BY | I5: =Cover!$M$37 | K5: REVISION DATE
G6: BLDG DESCRIP. | I6: =Cover!$G$32
A7: CUSTOMER: | C7: =Cover!$G$28 -> 0
A8: EAVE STRUTS
A9: QTY | B9: MARK | C9: DESCRIPTION | E9: PITCH | F9: PART | G9: PUNCH | H9: COLOR | J9: DWG # | K9: LENGTH | M9: WT.
A11: 1 | B11: 140ET1 | C11: Eave Strut (LSSS) | E11: 3.00 : 12 | F11: 12.25E14 | G11: N-R | H11: Pre-Galvanized | K11: 27'-5 1/2" | M11: 157.75
A12: IFlg= 3" 326.5"
A13: 1 | B13: 140ET2 | C13: Eave Strut (LSSS) | E13: 3.00 : 12 | F13: 12.25E14 | G13: R-N | H13: Pre-Galvanized | K13: 27'-5 1/2" | M13: 157.75
A14: IFlg= 3" 326.5"
A15: 1 | B15: 140ET3 | C15: Eave Strut (LSSS) | E15: 3.00 : 12 | F15: 12.25E14 | G15: ??-N | H15: Pre-Galvanized | K15: 27'-5 1/2" | M15: 157.75
A16: IFlg= 3" 10.75" 13.25" 326.5"
A17: 1 | B17: 140ET4 | C17: Eave Strut (LSSS) | E17: 3.00 : 12 | F17: 12.25E14 | G17: N-?? | H17: Pre-Galvanized | K17: 27'-5 1/2" | M17: 157.75
A18: IFlg= 3" 316.25" 318.75" 326.5"
K20: PAGE WEIGHT: | M20: =SUM(M11:M18) -> 631

Sheet Cold Form Members (CEE)
I1: SHIPPER NUMBER | K1: 2 | M1: OF | N1: =Cover!$M$22 -> 10
G2: JOB NUMBER | I2: =Cover!$G$24 -> 403184_Secondary | K2: ISSUE DATE | M2: =Cover!$G$27 -> 45985
G3: BUILDING NUMBER | K3: REVISION NUMBER
G4: DRAWN BY | I4: =Cover!$M$36 | K4: REVISION BY
G5: CHECKED BY | I5: =Cover!$M$37 | K5: REVISION DATE
G6: BLDG DESCRIP. | I6: =Cover!$G$32
A7: CUSTOMER: | C7: =Cover!$G$28 -> 0
A8: COLD FORM MEMBERS (CEE)
A9: QTY | B9: MARK | C9: DESCRIPTION | F9: PART | G9: PUNCH | H9: DWG # | I9: COLOR | K9: LENGTH | M9: WT.
A11: 2 | B11: 140DH1 | C11: Frame Opening Header | F11: 8X25C16 | G11: G-G | I11: Pre-Galvanized | K11: 13'-11 1/2" | M11: 78.02
A12: 5 | B12: 140DJ1 | C12: Framed Opening Jamb / Sub Jamb | F12: 8X35C16 | G12: G-G | I12: Pre-Galvanized | K12: 7'-1 11/16" | M12: 114.15
A13: Web= 46.25"
A14: 2 | B14: 140DJ3 | C14: Framed Opening Jamb / Sub Jamb | F14: 8X35C12 | G14: G-G | I14: Pre-Galvanized | K14: 17'-1 3/4" | M14: 193.84
A15: Web= 46.25" 88.25" 124.25" 166.25" 169.3125"
A16: 1 | B16: 140DJ6 | C16: Framed Opening Jamb / Sub Jamb | F16: 8X35C12 | G16: G-S | I16: Pre-Galvanized | K16: 5'-0 7/16" | M16: 28.48
A17: 1 | B17: 140DJ7 | C17: Framed Opening Jamb / Sub Jamb | F17: 8X35C12 | G17: G-S | I17: Pre-Galvanized | K17: 1'-6 15/16" | M17: 8.93
A18: 1 | B18: 140DJ8 | C18: Framed Opening Jamb / Sub Jamb | F18: 8X35C16 | G18: G-G | I18: Pre-Galvanized | K18: 7'-1 11/16" | M18: 22.83
A19: Web= 46.0625"
K21: PAGE WEIGHT: | M21: =SUM(M11:M19) -> 446.25

Sheet Cold Form Members (ZEE)
I1: SHIPPER NUMBER | K1: 3 | M1: OF | N1: =Cover!$M$22 -> 10
G2: JOB NUMBER | I2: =Cover!$G$24 -> 403184_Secondary | K2: ISSUE DATE | M2: =Cover!$G$27 -> 45985
G3: BUILDING NUMBER | K3: REVISION NUMBER
G4: DRAWN BY | I4: =Cover!$M$36 | K4: REVISION BY
G5: CHECKED BY | I5: =Cover!$M$37 | K5: REVISION DATE
G6: BLDG DESCRIP. | I6: =Cover!$G$32
A7: CUSTOMER: | C7: =Cover!$G$28 -> 0
A8: COLD FORM MEMBERS (ZEE)
A9: QTY | B9: MARK | C9: DESCRIPTION | F9: PART | G9: PUNCH | H9: DWG # | I9: COLOR | K9: LENGTH | M9: WT.
A11: 1 | B11: 140G1 | C11: Wall Girt | F11: 8X25Z16 | G11: S-S | I11: Pre-Galvanized | K11: 1'-7 11/16" | M11: 4.58
A12: 1 | B12: 140G2 | C12: Wall Girt | F12: 8X25Z16 | G12: S-G | I12: Pre-Galvanized | K12: 5'-11 1/2" | M12: 16.65
A13: Web= 22.1875" 57.75" 65.3125"
A14: 2 | B14: 140G3 | C14: Wall Girt | F14: 8X25Z16 | G14: S-G | I14: Pre-Galvanized | K14: 5'-11 1/2" | M14: 33.3
A15: Web= 22.1875" 57.75 66"
A16: 1 | B16: 140G4 | C16: Wall Girt | F16: 8X35Z12 | G16: B-B | I16: Pre-Galvanized | K16: 25'-1 1/2" | M16: 141.95
A17: Web= 12" 16" 78" 82" 89.5" 131.75" 197.75" 246" 253.5" 257.5"
A18: 4 | B18: 140G5 | C18: Wall Girt | F18: 8X25Z16 | G18: S-G | I18: Pre-Galvanized | K18: 1'-3 5/8" | M18: 14.56
A19: Web= 9.75"
A20: 4 | B20: 140G6 | C20: Wall Girt | F20: 8X25Z16 | G20: G-S | I20: Pre-Galvanized | K20: 1'-11 5/8" | M20: 22
A21: Web= 5.625"
A22: 1 | B22: 140G7 | C22: Wall Girt | F22: 8X25Z12 | G22: B-B | I22: Pre-Galvanized | K22: 30'-7 1/2" | M22: 151.2
A23: 1 | B23: 140G8 | C23: Wall Girt | F23: 8X35Z14 | G23: B-B | I23: Pre-Galvanized | K23: 30'-7 1/2" | M23: 116.34
A24: 1 | B24: 140G9 | C24: Wall Girt | F24: 8X25Z14 | G24: B-B | I24: Pre-Galvanized | K24: 30'-7 1/2" | M24: 101.57
A25: 1 | B25: 140G10 | C25: Wall Girt | F25: 8X35Z12 | G25: B-B | I25: Pre-Galvanized | K25: 30'-7 1/2" | M25: 173.03
A26: 1 | B26: 140G11 | C26: Wall Girt | F26: 8X25Z14 | G26: B-B | I26: Pre-Galvanized | K26: 22'-9 11/16" | M26: 75.65
A27: 1 | B27: 140G12 | C27: Wall Girt | F27: 8X35Z12 | G27: B-B | I27: Pre-Galvanized | K27: 29'-11 1/2" | M27: 169.27
A28: Web= 40.1875" 83.3125"
A29: 1 | B29: 140G13 | C29: Wall Girt | F29: 8X25Z12 | G29: B-B | I29: Pre-Galvanized | K29: 29'-11 1/2" | M29: 147.91
A30: 1 | B30: 140G14 | C30: Wall Girt | F30: 8X35Z12 | G30: B-B | I30: Pre-Galvanized | K30: 29'-11 1/2" | M30: 169.27
A31: 1 | B31: 140G15 | C31: Wall Girt | F31: 8X25Z16 | G31: S-S | I31: Pre-Galvanized | K31: 3'-1 11/16" | M31: 8.77
A32: 4 | B32: 140G16 | C32: Wall Girt | F32: 8X25Z16 | G32: B-B | I32: Pre-Galvanized | K32: 23'-1 1/2" | M32: 258.4
A33: Web= 264" 268"
A34: 1 | B34: 140G17 | C34: Wall Girt | F34: 8X25Z12 | G34: B-B | I34: Pre-Galvanized | K34: 29'-11 1/2" | M34: 147.91
A35: 1 | B35: 140G18 | C35: Wall Girt | F35: 8X25Z16 | G35: B-S | I35: Pre-Galvanized | K35: 23'-1 1/2" | M35: 64.6
A36: Web= 238" 264" 268"
K38: PAGE WEIGHT: | M38: =SUM(M11:M36) -> 1816.96

Sheet Cold Form Members (ZEE) (2)
I1: SHIPPER NUMBER | K1: 4 | M1: OF | N1: =Cover!$M$22 -> 10
G2: JOB NUMBER | I2: =Cover!$G$24 -> 403184_Secondary | K2: ISSUE DATE | M2: =Cover!$G$27 -> 45985
G3: BUILDING NUMBER | K3: REVISION NUMBER
G4: DRAWN BY | I4: =Cover!$M$36 | K4: REVISION BY
G5: CHECKED BY | I5: =Cover!$M$37 | K5: REVISION DATE
G6: BLDG DESCRIP. | I6: =Cover!$G$32
A7: CUSTOMER: | C7: =Cover!$G$28 -> 0
A8: COLD FORM MEMBERS (ZEE)
A9: QTY | B9: MARK | C9: DESCRIPTION | F9: PART | G9: PUNCH | H9: DWG # | I9: COLOR | K9: LENGTH | M9: WT.
A11: 1 | B11: 140G19 | C11: Wall Girt | F11: 8X25Z16 | G11: B-B | I11: Pre-Galvanized | K11: 17'-9 3/4" | M11: 49.76
A12: 1 | B12: 140G20 | C12: Wall Girt | F12: 8X25Z14 | G12: B-B | I12: Pre-Galvanized | K12: 23'-1 1/2" | M12: 76.7
A13: Web= 9.5" 13.5" 18.1875" 61.31252
A14: 2 | B14: 140G21 | C14: Wall Girt | F14: 8X25Z16 | G14: B-B | I14: Pre-Galvanized | K14: 23'-1 1/2" | M14: 129.2
A15: Web= 9.5" 13.5" 18.1875" 61.3125"
A16: 1 | B16: 140G22 | C16: Wall Girt | F16: 8X25Z16 | G16: S-B | I16: Pre-Galvanized | K16: 23'-1 1/2" | M16: 64.6
A17: Web= 9.5" 13.5" 39.5"
A18: 1 | B18: 140G23 | C18: Wall Girt | F18: 8X25Z16 | G18: S-S | I18: Pre-Galvanized | K18: 1'-3 1/4" | M18: 3.55
A19: 1 | B19: 140G24 | C19: Wall Girt | F19: 8X35Z12 | G19: B-A | I19: Pre-Galvanized | K19: 21'-1 1/2" | M19: 119.36
A20: Web= 41.5" 45.5" 48.125" 53.5" 55.5" 57.5" 61.5" 67.5" 71.5" 79.5" 83.5" 109.75" 181.75" 219.375"
A21: 1 | B21: 140G25 | C21: Wall Girt | F21: 8X35Z12 | G21: G-A | I21: Pre-Galvanized | K21: 17'-11 1/4" | M21: 101.34
A22: Web= 9.5" 11.5" 13.5" 17.5" 23.5" 27.5" 35.5" 39.5" 51.5" 63.75" 67.75" 75.25" 117.5"
A23: 1 | B23: 140G26 | C23: Wall Girt | F23: 8X25Z12 | G23: B-B | I23: Pre-Galvanized | K23: 30'-7 1/2" | M23: 151.2
A24: Web= 303.75" 307.75"
A25: 2 | B25: 140G27 | C25: Wall Girt | F25: 8X25Z14 | G25: B-B | I25: Pre-Galvanized | K25: 30'-7 1/2" | M25: 203.14
A26: 1 | B26: 140G28 | C26: Wall Girt | F26: 8X35Z12 | G26: B-B | I26: Pre-Galvanized | K26: 30'-7 1/2" | M26: 173.03
A27: 2 | B27: 140G29 | C27: Wall Girt | F27: 8X25Z12 | G27: B-B | I27: Pre-Galvanized | K27: 29'-11 1/2" " | M27: 295.82
A28: 1 | B28: 140G30 | C28: Wall Girt | F28: 8X35Z12 | G28: B-B | I28: Pre-Galvanized | K28: 29'-11 1/2" | M28: 169.27
A29: 2 | B29: 140P1 | C29: Roof Purlin | F29: 12X35Z14 | G29: S-S | I29: Pre-Galvanized | K29: 26'-11 1/2" | M29: 255.82
A30: 5 | B30: 140P2 | C30: Roof Purlin | F30: 12X35Z12 | G30: B-B | I30: Pre-Galvanized | K30: 30'-7 1/2" | M30: 1083.45
A31: Web= 45.75" 295.75" 299.75" 303.75" 307.75" 315.75" 319.75" 323.75" 333.75" 345.75" 353.75"
A32: 5 | B32: 140P3 | C32: Roof Purlin | F32: 12X35Z12 | G32: B-B | I32: Pre-Galvanized | K32: 30'-7 1/2" | M32: 1083.45
A33: Web= 13.75" 21.75" 33.75" 43.75" 47.75" 51.75" 59.75" 63.75" 67.75" 71.75" 321.75" 333.75" 337.75"
A34: 5 | B34: 140P4 | C34: Roof Purlin | F34: 12X35Z12 | G34: B-S | I34: Pre-Galvanized | K34: 30'-7 1/2" | M34: 1083.45
A35: Web= 29.75 33.75" 323.50" 327.50" 353.50" 357.50"
K37: PAGE WEIGHT: | M37: =SUM(M11:M35) -> 5043.14

Sheet Cold Form Members (ZEE) (3)
I1: SHIPPER NUMBER | K1: 5 | M1: OF | N1: =Cover!$M$22 -> 10
G2: JOB NUMBER | I2: =Cover!$G$24 -> 403184_Secondary | K2: ISSUE DATE | M2: =Cover!$G$27 -> 45985
G3: BUILDING NUMBER | K3: REVISION NUMBER
G4: DRAWN BY | I4: =Cover!$M$36 | K4: REVISION BY
G5: CHECKED BY | I5: =Cover!$M$37 | K5: REVISION DATE
G6: BLDG DESCRIP. | I6: =Cover!$G$32
A7: CUSTOMER: | C7: =Cover!$G$28 -> 0
A8: COLD FORM MEMBERS (ZEE)
A9: QTY | B9: MARK | C9: DESCRIPTION | F9: PART | G9: PUNCH | H9: DWG # | I9: COLOR | K9: LENGTH | M9: WT.
A11: 5 | B11: 140P5 | C11: Roof Purlin | F11: 12X35Z12 | G11: S-B | I11: Pre-Galvanized | K11: 30'-7 1/2" | M11: 1083.45
A12: Web= 10.00" 14.00" 40.00" 44.00"
A13: 1 | B13: 140P_EXT1 | C13: Roof Purlin | F13: 8X25Z12 | I13: Pre-Galvanized | K13: 40'-0" | M13: 197.49
A14: 1 | B14: 140P_EXT2 | C14: Roof Purlin | F14: 12X35Z12 | I14: Pre-Galvanized | K14: 30'-7 1/2" | M14: 216.69
A15: 1 | B15: 140P_EXT3 | C15: Roof Purlin | F15: 8X35Z12 | I15: Pre-Galvanized | K15: 30'-7 1/2" | M15: 173.03
K17: PAGE WEIGHT: | M17: =SUM(M11:N15) -> 1670.66

Sheet Misc. Cold Form
I1: SHIPPER NUMBER | K1: 6 | M1: OF | N1: =Cover!$M$22 -> 10
G2: JOB NUMBER | I2: =Cover!$G$24 -> 403184_Secondary | K2: ISSUE DATE | M2: =Cover!$G$27 -> 45985
G3: BUILDING NUMBER | K3: REVISION NUMBER
G4: DRAWN BY | I4: =Cover!$M$36 | K4: REVISION BY
G5: CHECKED BY | I5: =Cover!$M$37 | K5: REVISION DATE
G6: BLDG DESCRIP. | I6: =Cover!$G$32
A7: CUSTOMER: | C7: =Cover!$G$28 -> 0
A8: MISCELLANEOUS COLD FORM
A9: QTY | B9: MARK | C9: DESCRIPTION | F9: PART | G9: DWG # | H9: COLOR | J9: LENGTH | M9: WT.
A11: 1 | B11: 140BC1 | C11: Base Angle | F11: 8X25C16 | G11: BA1 | H11: Pre-Galvanized | J11: 20'- 0" | M11: =27.95*2*A11 -> 55.9
A12: 1 | B12: 140BC2 | C12: Base Angle | F12: 8X25C16 | G12: BA1 | H12: Pre-Galvanized | J12: 20'- 0" | M12: =27.95*2*A12 -> 55.9
A13: 1 | B13: 140BC3 | C13: Base Angle | F13: 8X25C16 | G13: BA1 | H13: Pre-Galvanized | J13: 20'- 0" | M13: =27.95*2*A13 -> 55.9
A14: 1 | B14: 140BC4 | C14: Base Angle | F14: 8X25C16 | G14: BA1 | H14: Pre-Galvanized | J14: 20'- 0" | M14: =27.95*2*A14 -> 55.9
A15: 1 | B15: 140BC5 | C15: Base Angle | F15: 8X25C16 | G15: BA1 | H15: Pre-Galvanized | J15: 20'- 0" | M15: =27.95*2*A15 -> 55.9
A16: 3 | B16: 140BC6 | C16: Base Angle | F16: 8X25C16 | G16: BA1 | H16: Pre-Galvanized | J16: 20'- 0" | M16: =27.95*2*A16 -> 167.7
A17: 1 | B17: 140BC7 | C17: Base Angle | F17: 8X25C16 | G17: BA1 | H17: Pre-Galvanized | J17: 20'- 0" | M17: =27.95*2*A17 -> 55.9
A18: 2 | B18: 140BC8 | C18: Base Angle | F18: 8X25C16 | G18: BA1 | H18: Pre-Galvanized | J18: 20'- 0" | M18: =27.95*2*A18 -> 111.8
A19: 1 | B19: 140BC9 | C19: Base Angle | F19: 8X25C16 | G19: BA1 | H19: Pre-Galvanized | J19: 20'- 0" | M19: =27.95*2*A19 -> 55.9
A20: 1 | B20: 140BC_EXT1 | C20: Base Angle | F20: 8X25C16 | G20: BA1 | H20: Pre-Galvanized | J20: 20'- 0" | M20: =27.95*A20 -> 27.95
A21: 5 | B21: 140SA1 | C21: Sheeting Angle | F21: 4X2X16Ga | G21: SA1 | H21: Pre-Galvanized | J21: 20'- 0" | M21: =(M22/4)*5 -> 120.95
A22: 4 | B22: 140SA2 | C22: Sheeting Angle | F22: 4X2X16Ga | G22: SA1 | H22: Pre-Galvanized | J22: 20'- 0" | M22: 96.76
A23: 1 | B23: 140SA_EXT1 | C23: Sheeting Angle | F23: 4X2X16Ga | G23: SA1 | H23: Pre-Galvanized | J23: 10'- 0" | M23: 12.1
A24: 3 | B24: 140GH1 | C24: 8" Girt Header (8 1/4CX6X4) | F24: 17 7/8X14Ga | G24: GH-1 | H24: Pre-Galvanized | J24: 3'-3 1/2" | M24: 45.87
A25: 12 | B25: 140SSL1 | C25: Eave Strut Spacer ( 3 : 12) | F25: 10X35C14 | G25: SSL-10 | H25: Pre-Galvanized | J25: 6" | M25: 26.76
K27: PAGE WEIGHT: | M27: =SUM(M21:M25) -> 302.44

Sheet Clips
I1: SHIPPER NUMBER | K1: 7 | M1: OF | N1: =Cover!$M$22 -> 10
G2: JOB NUMBER | I2: =Cover!$G$24 -> 403184_Secondary | K2: ISSUE DATE | M2: =Cover!$G$27 -> 45985
G3: BUILDING NUMBER | K3: REVISION NUMBER
G4: DRAWN BY | I4: =Cover!$M$36 | K4: REVISION BY
G5: CHECKED BY | I5: =Cover!$M$37 | K5: REVISION DATE
G6: BLDG DESCRIP. | I6: =Cover!$G$32
A7: CUSTOMER: | C7: =Cover!$G$28 -> 0
A8: CLIPS
A9: QTY | B9: MARK | D9: DESCRIPTION | I9: COLOR | K9: DRAWING # | M9: WT.
A11: 1 | B11: 140CCF2 | D11: Clip | I11: Pre-Galvanized | K11: 140CCF2 | M11: 2.15
A12: 1 | B12: 140CCF4 | D12: Clip | I12: Pre-Galvanized | K12: 140CCF4 | M12: 2.15
A13: 1 | B13: 140CCF6 | D13: Clip | I13: Pre-Galvanized | K13: 140CCF6 | M13: 2.43
A14: 1 | B14: 140CCF7 | D14: Sheeting Clip | I14: Pre-Galvanized | K14: CL-5 | M14: 0.58
K17: PAGE WEIGHT: | M17: =SUM(M11:M15) -> 7.31

Sheet Pre-Galv Clips
I1: SHIPPER NUMBER | K1: 8 | M1: OF | N1: =Cover!$M$22 -> 10
G2: JOB NUMBER | I2: =Cover!$G$24 -> 403184_Secondary | K2: ISSUE DATE | M2: =Cover!$G$27 -> 45985
G3: BUILDING NUMBER | K3: REVISION NUMBER
G4: DRAWN BY | I4: =Cover!$M$36 | K4: REVISION BY
G5: CHECKED BY | I5: =Cover!$M$37 | K5: REVISION DATE
G6: BLDG DESCRIP. | I6: =Cover!$G$32
A7: CUSTOMER: | C7: =Cover!$G$28 -> 0
A8: PRE-GALVANIZED CLIPS
A9: QTY | B9: MARK | D9: DESCRIPTION | I9: COLOR | K9: DRAWING # | M9: WT.
A11: 33 | B11: 140CCF1 | D11: Girt / Jamb Clip | I11: Pre-Galvanized | K11: CL103 | M11: 70.95
A12: 10 | B12: 140CCF3 | D12: Jamb Base Clip | I12: Pre-Galvanized | K12: CL104 | M12: 13.4
A13: 4 | B13: 140CCF5 | D13: Header to Jamb Clip | I13: Pre-Galvanized | K13: CL100 | M13: 5.36
A14: 2 | B14: 140CCF_EXT1 | D14: Girt / Jamb Clip | I14: Pre-Galvanized | K14: CL103 | M14: 4.3
A15: 2 | B15: 140CCF_EXT2 | D15: Jamb Base Clip | I15: Pre-Galvanized | K15: CL104 | M15: 2.7
A16: 2 | B16: 140CCF_EXT3 | D16: Header to Jamb Clip | I16: Pre-Galvanized | K16: CL100 | M16: 2.7
K19: PAGE WEIGHT: | M19: =SUM(M11:M17) -> 99.41

Sheet Standing Seam Hardware
I1: SHIPPER NUMBER | K1: 9 | M1: OF | N1: =Cover!$M$22 -> 10
G2: JOB NUMBER | I2: =Cover!$G$24 -> 403184_Secondary | K2: ISSUE DATE | M2: =Cover!$G$27 -> 45985
G3: BUILDING NUMBER | K3: REVISION NUMBER
G4: DRAWN BY | I4: =Cover!$M$36 | K4: REVISION BY
G5: CHECKED BY | I5: =Cover!$M$37 | K5: REVISION DATE
G6: BLDG DESCRIP. | I6: =Cover!$G$32
A7: CUSTOMER: | C7: =Cover!$G$28 -> 0
A8: STANDING SEAM HARDWARE
A9: QTY | B9: MARK | C9: DESCRIPTION | G9: DWG # | H9: COLOR | J9: LENGTH | M9: WT.
A11: 4 | B11: STRP1 | C11: Rolls of Strapping | G11: STRP1 | H11: White | J11: 175'- 0" | M11: =22*A11 -> 88
K14: PAGE WEIGHT: | M14: =SUM(M11:M12) -> 88

Sheet Screws
I1: SHIPPER NUMBER | K1: 10 | M1: OF | N1: =Cover!$M$22 -> 10
G2: JOB NUMBER | I2: =Cover!$G$24 -> 403184_Secondary | K2: ISSUE DATE | M2: =Cover!$G$27 -> 45985
G3: BUILDING NUMBER | K3: REVISION NUMBER
G4: DRAWN BY | I4: =Cover!$M$36 | K4: REVISION BY
G5: CHECKED BY | I5: =Cover!$M$37 | K5: REVISION DATE
G6: BLDG DESCRIP. | I6: =Cover!$G$32
A7: CUSTOMER: | C7: =Cover!$G$28 -> 0
A8: SCREWS
A9: QTY | B9: MARK | C9: DESCRIPTION | H9: COLOR | J9: LENGTH | M9: WT.
A11: =4*12*6 -> 288 | C11: #10-16 x 1"- Pancake Self Driller | H11: Plain | J11: 1"
A12: 494 | C12: #12 x 1" Self Driller (No Washer) | H12: Plain | J12: 1"
K38: PAGE WEIGHT: | M38: =SUM(M11:M36) -> 0

Sheet 34
I1: SHIPPER NUMBER | K1: ="@PgNo" -> @PgNo | M1: OF | N1: =Cover!$M$22 -> 10
G2: JOB NUMBER | I2: =Cover!$G$24 -> 403184_Secondary | K2: ISSUE DATE | M2: =Cover!$G$27 -> 45985
G3: BUILDING NUMBER | K3: REVISION NUMBER
G4: DRAWN BY | I4: =Cover!$M$36 | K4: REVISION BY
G5: CHECKED BY | I5: =Cover!$M$37 | K5: REVISION DATE
G6: BLDG DESCRIP. | I6: =Cover!$G$32
A7: CUSTOMER: | C7: =Cover!$G$28 -> 0
A8: PURCHASE - CRANE RAILS & HOOK BOLTS
A9: QTY | B9: DESCRIPTION | K9: LENGTH | M9: WT.
B11: Rail runs with Splice Bars, Bolts & Standard Punching for hook bolts, 4" apart , 24" on center
C12: LB/YD
C13: Hook Bolt Diameter
B15: Hook bolts with (1) nut each to fit:
C16: Hook Bolt Diameter
C17: Rail (LB/YD)
C18: Channel Cap Size
B21: Rail runs with Splice Bars, Bolts & Standard Punching for hook bolts, 4" apart , 24" on center
C22: LB/YD
C23: Hook Bolt Diameter
B25: Hook bolts with (1) nut each to fit:
C26: Hook Bolt Diameter
C27: Rail (LB/YD)
C28: Channel Cap Size
K39: PAGE WEIGHT: | M39: =SUM(M11:M37) -> 0

Sheet 33
I1: SHIPPER NUMBER | K1: ="@PgNo" -> @PgNo | M1: OF | N1: =Cover!$M$22 -> 10
G2: JOB NUMBER | I2: =Cover!$G$24 -> 403184_Secondary | K2: ISSUE DATE | M2: =Cover!$G$27 -> 45985
G3: BUILDING NUMBER | K3: REVISION NUMBER
G4: DRAWN BY | I4: =Cover!$M$36 | K4: REVISION BY
G5: CHECKED BY | I5: =Cover!$M$37 | K5: REVISION DATE
G6: BLDG DESCRIP. | I6: =Cover!$G$32
A7: CUSTOMER: | C7: =Cover!$G$28 -> 0
A8: BUYOUT ITEMS
A9: QTY | B9: MARK | C9: DESCRIPTION | H9: COLOR | J9: LENGTH | M9: WT.
A11: ="@Data" -> @Data
K39: PAGE WEIGHT: | M39: =SUM(M11:M37) -> 0

Sheet Logos-ASB2

Sheet Data Page
A1: Colors | D1: Cees | E1: Zees | G1: Roof Colors | J1: Screw Colors | M1: Mastic Color | P1: Trim Marks
A2: Almond (Kynar) | D2: 4X2C16 | E2: 4X2Z16 | G2: Almond (Kynar) | J2: Almond (Kynar) | M2: Almond | P2: FL-10 | Q2: Corner Trim (PBR/A Panel) | R2: =$P2 & " " & $Q2 -> FL-10 Corner Trim (PBR/A Panel) | Y2: C8X11.5 | AF2: Screws | AH2: ScrewLength | AL2: SSRSkylight
A3: Ash Gray | D3: 4X2C14 | E3: 4X2Z14 | G3: Ash Gray | J3: Ash Gray | M3: Bronze | P3: FL-11 | Q3: Corner Trim (PBU Panel) | R3: =$P3 & " " & $Q3 -> FL-11 Corner Trim (PBU Panel) | Y3: C8X13.75 | AF3: #10-16 x 1"- Pancake Self Driller | AH3: 1" | AL3: TS-324 Skylight
A4: Aztec Gold | D4: 4X25C16 | E4: 4X25Z16 | G4: Aztec Gold | J4: Aztec Gold | M4: Gray | P4: FL-12 | Q4: Inside Corner Trim (PBR Panel) | R4: =$P4 & " " & $Q4 -> FL-12 Inside Corner Trim (PBR Panel) | Y4: C8X18.75 | AF4: #12 x 1 1/2" Self Driller (Long Life) | AH4: 1 1/2" | AL4: TS-324 Insulated Skylight
A5: Bone White (Kynar) | D5: 4X25C14 | E5: 4X25Z14 | G5: Bone White (Kynar) | J5: Brownstone (Kynar) | M5: White | P5: FL-13 | Q5: Inside Corner Trim (PBU Panel) | R5: =$P5 & " " & $Q5 -> FL-13 Inside Corner Trim (PBU Panel) | Y5: C10X15.3 | AF5: #12 x 1 1/2" Self Driller w/ Washer | AH5: 1 1/2" | AL5: VS-216 Skylight
A6: Brownstone (Kynar) | D6: 6X25C16 | E6: 6X25Z16 | G6: Brownstone (Kynar) | J6: Burgundy | P6: FL-14 | Q6: Starter Trim (A Panel) | R6: =$P6 & " " & $Q6 -> FL-14 Starter Trim (A Panel) | Y6: C10X20 | AF6: #12 x 1 1/4" Self Driller (Long Life) | AH6: 1 1/4" | AL6: VS-216 Insulated Skylight
A7: Burgundy | D7: 6X25C14 | E7: 6X25Z14 | G7: Burgundy | J7: Burnished Slate | P7: FL-15 | Q7: Box Rake (PBR Panel) | R7: =$P7 & " " & $Q7 -> FL-15 Box Rake (PBR Panel) | Y7: C10X25 | AF7: #12 x 1 1/4" Self Driller w/ Washer | AH7: 1 1/4"
A8: Burnished Slate | D8: 8X25C16 | E8: 8X25Z16 | G8: Burnished Slate | J8: Charcoal Gray | P8: FL-16 | Q8: Box Rake End Cap | R8: =$P8 & " " & $Q8 -> FL-16 Box Rake End Cap | Y8: C10X30 | AF8: #12 x 1" Self Driller (No Washer) | AH8: 1"
A9: Charcoal Gray | D9: 8X25C14 | E9: 8X25Z14 | G9: Charcoal Gray | J9: Classic Green (Kynar) | P9: FL-18 | Q9: Box Rake (PBU Panel) | R9: =$P9 & " " & $Q9 -> FL-18 Box Rake (PBU Panel) | Y9: C12X20 | AF9: #12 x 1 1/2" Tek 5 | AH9: 1 1/2"
A10: Classic Green (Kynar) | D10: 8X25C12 | E10: 8X25Z12 | G10: Classic Green (Kynar) | J10: Colonial Red (Kynar) | M10: PreGal Color | P10: FL-21 | Q10: Rake Trim (PBR Panel) | R10: =$P10 & " " & $Q10 -> FL-21 Rake Trim (PBR Panel) | Y10: C12X25 | AF10: #12 x 2" Self Driller (Long Life) | AH10: 2"
A11: Colonial Red (Kynar) | D11: 8X35C16 | E11: 8X35Z16 | G11: Colonial Red (Kynar) | J11: Colony Green | M11: Pre-Galvanized | P11: FL-21 R | Q11: Rake Trim Mitered Rt (PBR Panel) | R11: =$P11 & " " & $Q11 -> FL-21 R Rake Trim Mitered Rt (PBR Panel) | Y11: C12X30 | AF11: #12 x 2" Self Driller w/ Washer | AH11: 2"
A12: Colony Green | D12: 8X35C14 | E12: 8X35Z14 | G12: Colony Green | J12: Crimson Red | P12: FL-21 L | Q12: Rake Trim Mitered Lt (PBR Panel) | R12: =$P12 & " " & $Q12 -> FL-21 L Rake Trim Mitered Lt (PBR Panel) | Y12: W8X10 | AF12: #14 x 7/8" LapTek Self Driller | AH12: 7/8"
A13: Crimson Red | D13: 8X35C12 | E13: 8X35Z12 | G13: Crimson Red | J13: Desert Sand | P13: FL-22 | Q13: Rake Trim End Cap (PBR Panel) | R13: =$P13 & " " & $Q13 -> FL-22 Rake Trim End Cap (PBR Panel) | Y13: W8X13 | AF13: #14 x 7/8" LapTek Self Driller (Long Life) | AH13: 7/8"
A14: Desert Sand | D14: 10X25C16 | E14: 10X25Z16 | G14: Desert Sand | J14: Evergreen | M14: Bolt Color | P14: FL-23 | Q14: Peak Box ( Sign ) | R14: =$P14 & " " & $Q14 -> FL-23 Peak Box ( Sign ) | Y14: W8X15 | AF14: 1/4-14 x 1 1/2" Self Driller (No Washer) | AH14: 1 1/2"
A15: Evergreen | D15: 10X25C14 | E15: 10X25Z14 | G15: Evergreen | J15: Fern Green | M15: Zinc Plated | P15: FL-24 | Q15: Rake Trim (PBU Panel) | R15: =$P15 & " " & $Q15 -> FL-24 Rake Trim (PBU Panel) | Y15: W8X18 | AF15: 1/4-14 x 1 1/4" Self Driller (Long Life) | AH15: 1 1/4"
A16: Fern Green | D16: 10X25C12 | E16: 10X25Z12 | G16: Fern Green | J16: Gallery Blue (Kynar) | M16: Hot Dipped Galvanized | P16: FL-24 R | Q16: Rake Trim Mitered Rt (PBU Panel) | R16: =$P16 & " " & $Q16 -> FL-24 R Rake Trim Mitered Rt (PBU Panel) | Y16: W8X21 | AF16: 1/4-14 x 1 1/4" Shoulder SDS | AH16: 1 1/4"
A17: Gallery Blue (Kynar) | D17: 10X35C14 | E17: 10X35Z14 | G17: Gallery Blue (Kynar) | J17: Galvalume | P17: FL-24 L | Q17: Rake Trim Mitered Lt (PBU Panel) | R17: =$P17 & " " & $Q17 -> FL-24 L Rake Trim Mitered Lt (PBU Panel) | Y17: W8X24 | AF17: 1/4-14 x 7/8" Self Driller (Long Life) | AH17: 7/8"
A18: Galvalume | D18: 10X35C12 | E18: 10X35Z12 | G18: Galvalume | J18: Galvanized | P18: FL-26 | Q18: Peak Box ( Sign ) | R18: =$P18 & " " & $Q18 -> FL-26 Peak Box ( Sign ) | Y18: W8X28 | AF18: 1/8" x 3/16" Pop Rivets | AH18: 3/16"
A19: Galvanized | D19: 12X25C14 | E19: 12X25Z14 | G19: Galvanized | J19: Hawaiian Blue | P19: FL-27 | Q19: High Side Eave Trim (PBR Panel) | R19: =$P19 & " " & $Q19 -> FL-27 High Side Eave Trim (PBR Panel) | Y19: W8X31 | AF19: 12-24 x 1 1/4" Tek 5 w/ Washer | AH19: 1 1/4"
A20: Hawaiian Blue | D20: 12X25C12 | E20: 12X25Z12 | G20: Hawaiian Blue | J20: Koko Brown | P20: FL-27 R | Q20: High Side Eave Trim Mitered Rt (PBR Panel) | R20: =$P20 & " " & $Q20 -> FL-27 R High Side Eave Trim Mitered Rt (PBR Panel) | Y20: W8X35 | AF20: #14 x 1 1/4" (Long Life) w/O.D. Washer | AH20: 1 1/4"
A21: Koko Brown | D21: 12X35C14 | E21: 12X35Z14 | G21: Koko Brown | J21: Light Stone | M21: CoatingsMinus | P21: FL-27 L | Q21: High Side Eave Trim Mitered Lt (PBR Panel) | R21: =$P21 & " " & $Q21 -> FL-27 L High Side Eave Trim Mitered Lt (PBR Panel) | Y21: W8X40 | AF21: #14 x 7/8" LapTek (Long Life) w/O.D. Washer | AH21: 7/8"
A22: Light Stone | D22: 12X35C12 | E22: 12X35Z12 | G22: Light Stone | J22: Midnight Brz (Kynar) | M22: Gray Primer | P22: FL-28 R | Q22: High Side End Cap Rt (PBR Panel) | R22: =$P22 & " " & $Q22 -> FL-28 R High Side End Cap Rt (PBR Panel) | Y22: W8X48
A23: Medium Brz (Kynar) | G23: Medium Brz (Kynar) | J23: Polar White | M23: Hot Dipped Galvanized | P23: FL-28 L | Q23: High Side End Cap Lt (PBR Panel) | R23: =$P23 & " " & $Q23 -> FL-28 L High Side End Cap Lt (PBR Panel) | Y23: W8X58
A24: Midnight Brz (Kynar) | G24: Midnight Brz (Kynar) | J24: Regal Red (Kynar) | M24: Red Oxide | P24: FL-29 | Q24: Low Side Eave Trim (PBR Panel) | R24: =$P24 & " " & $Q24 -> FL-29 Low Side Eave Trim (PBR Panel) | Y24: W8X67
A25: Polar White | G25: Polar White | J25: Rustic Red | P25: FL-29 R | Q25: Low Side Eave Trim Mitered Rt (PBR Panel) | R25: =$P25 & " " & $Q25 -> FL-29 R Low Side Eave Trim Mitered Rt (PBR Panel) | Y25: W10X12
A26: Regal Red (Kynar) | G26: Regal Red (Kynar) | J26: Saddle Tan | P26: FL-29 L | Q26: Low Side Eave Trim Mitered Lt (PBR Panel) | R26: =$P26 & " " & $Q26 -> FL-29 L Low Side Eave Trim Mitered Lt (PBR Panel) | Y26: W10X15
A27: Rustic Red | G27: Rustic Red | J27: Slate Gray (Kynar) | P27: FL-30 R | Q27: Low Side End Cap Rt (PBR Panel) | R27: =$P27 & " " & $Q27 -> FL-30 R Low Side End Cap Rt (PBR Panel) | Y27: W10X17
A28: Saddle Tan | G28: Saddle Tan | J28: Snow White (Kynar) | P28: FL-30 L | Q28: Low Side End Cap Lt (PBR Panel) | R28: =$P28 & " " & $Q28 -> FL-30 L Low Side End Cap Lt (PBR Panel) | Y28: W10X19
A29: Slate Gray (Kynar) | G29: Slate Gray (Kynar) | J29: Solar White | P29: FL-31 | Q29: Eave Trim (Simple) | R29: =$P29 & " " & $Q29 -> FL-31 Eave Trim (Simple) | Y29: W10X22
A30: Solar White | G30: Snow White (Kynar) | J30: Plain | P30: FL-32 | Q30: Eave Gutter (PBR Panel) | R30: =$P30 & " " & $Q30 -> FL-32 Eave Gutter (PBR Panel) | Y30: W10X26
A31: Snow White (Kynar) | G31: Solar White | P31: FL-32 R | Q31: Eave Gutter Mitered Rt (PBR Panel) | R31: =$P31 & " " & $Q31 -> FL-32 R Eave Gutter Mitered Rt (PBR Panel) | Y31: W10X30
E32: Saved? | G32: White | P32: FL-32 L | Q32: Eave Gutter Mitered Lt (PBR Panel) | R32: =$P32 & " " & $Q32 -> FL-32 L Eave Gutter Mitered Lt (PBR Panel) | Y32: W10X33
E33: No | P33: FL-33 R | Q33: Gutter End Cap Rt (PBR Panel) | R33: =$P33 & " " & $Q33 -> FL-33 R Gutter End Cap Rt (PBR Panel) | Y33: W10X39
A34: Coatings | D34: Cold Form | F34: Eave Struts | H34: Flange Braces | K34: Bolts | P34: FL-33 L | Q34: Gutter End Cap Lt (PBR Panel) | R34: =$P34 & " " & $Q34 -> FL-33 L Gutter End Cap Lt (PBR Panel) | Y34: W10X45
A35: Gray Primer | D35: 4X2C16 | F35: 4E16 | H35: 2X2X14Ga | K35: 1/2" x 1" A307 Low Carbon Bolt w/ Nut | L35: 1" | P35: FL-34 | Q35: Eave Gutter (PBU Panel) | R35: =$P35 & " " & $Q35 -> FL-34 Eave Gutter (PBU Panel) | Y35: W10X49
A36: Hot Dipped Galvanized | D36: 4X2C14 | F36: 4E14 | H36: 2X2X1/8 | K36: 1/2" x 1 1/4" A307 Low Carbon Bolt w/ Nut | L36: 1 1/4" | P36: FL-34 R | Q36: Eave Gutter Mitered Rt (PBU Panel) | R36: =$P36 & " " & $Q36 -> FL-34 R Eave Gutter Mitered Rt (PBU Panel) | Y36: W10X54
A37: Pre-Galvanized | D37: 4X25C16 | F37: 6E16 | H37: 3X2X3/16 | K37: 1/2" x 1" A307 Fin Neck Bolt w/ Nut | L37: 1" | P37: FL-34 L | Q37: Eave Gutter Mitered Lt (PBU Panel) | R37: =$P37 & " " & $Q37 -> FL-34 L Eave Gutter Mitered Lt (PBU Panel) | Y37: W10X60
A38: Red Oxide | D38: 4X25C14 | F38: 6E14 | H38: 3X3X3/16 | K38: 1/2" x 1 1/4" A307 Fin Neck Bolt w/ Nut | L38: 1 1/4" | P38: FL-35 R | Q38: Eave Gutter End Cap Rt (PBU Panel) | R38: =$P38 & " " & $Q38 -> FL-35 R Eave Gutter End Cap Rt (PBU Panel) | Y38: W10X68
D39: 6X25C16 | F39: 6E12 | K39: 1/2" x 1 1/4" A325 Bolt w/ Hi-Str. Nut | L39: 1 1/4" | P39: FL-35 L | Q39: Eave Gutter End Cap Lt (PBU Panel) | R39: =$P39 & " " & $Q39 -> FL-35 L Eave Gutter End Cap Lt (PBU Panel) | Y39: W10X77
D40: 6X25C14 | F40: 8E14 | K40: 1/2" x 1 1/2" A325 Bolt w/ Hi-Str. Nut | L40: 1 1/2" | P40: FL-36 | Q40: Eave Gutter (Box Hang On) (PBU Panel) | R40: =$P40 & " " & $Q40 -> FL-36 Eave Gutter (Box Hang On) (PBU Panel) | Y40: W10X88
...

Sheet AdjShip
A11: Quantity | B11: Mark | C11: Part/Description | D11: Color | E11: Drawing | F11: Length | G11: LengthCut | H11: Punch | I11: Inches

Sheet 1
I1: SHIPPER NUMBER | K1: ="@PgNo" -> @PgNo | M1: OF | N1: =Cover!$M$22 -> 10
G2: JOB NUMBER | I2: =Cover!$G$24 -> 403184_Secondary | K2: ISSUE DATE | M2: =Cover!$G$27 -> 45985
G3: BUILDING NUMBER | K3: REVISION NUMBER
G4: DRAWN BY | I4: =Cover!$M$36 | K4: REVISION BY
G5: CHECKED BY | I5: =Cover!$M$37 | K5: REVISION DATE
G6: BLDG DESCRIP. | I6: =Cover!$G$32
A7: CUSTOMER: | C7: =Cover!$G$28 -> 0
A8: MAIN FRAME BUILT UP
A9: QTY | B9: MARK | C9: DESCRIPTION | G9: DWG # | H9: COLOR | J9: LENGTH | M9: WT.
A11: ="@Data" -> @Data
R25: `
K39: PAGE WEIGHT: | M39: =SUM(M11:M37) -> 0

Sheet 2
I1: SHIPPER NUMBER | K1: ="@PgNo" -> @PgNo | M1: OF | N1: =Cover!$M$22 -> 10
G2: JOB NUMBER | I2: =Cover!$G$24 -> 403184_Secondary | K2: ISSUE DATE | M2: =Cover!$G$27 -> 45985
G3: BUILDING NUMBER | K3: REVISION NUMBER
G4: DRAWN BY | I4: =Cover!$M$36 | K4: REVISION BY
G5: CHECKED BY | I5: =Cover!$M$37 | K5: REVISION DATE
G6: BLDG DESCRIP. | I6: =Cover!$G$32
A7: CUSTOMER: | C7: =Cover!$G$28 -> 0
A8: MAIN FRAME HOT ROLLED
A9: QTY | B9: MARK | C9: DESCRIPTION | F9: PART | G9: DWG # | H9: COLOR | J9: LENGTH | M9: WT.
A11: ="@Data" -> @Data
K39: PAGE WEIGHT: | M39: =SUM(M11:M37) -> 0

Sheet 3
I1: SHIPPER NUMBER | K1: ="@PgNo" -> @PgNo | M1: OF | N1: =Cover!$M$22 -> 10
G2: JOB NUMBER | I2: =Cover!$G$24 -> 403184_Secondary | K2: ISSUE DATE | M2: =Cover!$G$27 -> 45985
G3: BUILDING NUMBER | K3: REVISION NUMBER
G4: DRAWN BY | I4: =Cover!$M$36 | K4: REVISION BY
G5: CHECKED BY | I5: =Cover!$M$37 | K5: REVISION DATE
G6: BLDG DESCRIP. | I6: =Cover!$G$32
A7: CUSTOMER: | C7: =Cover!$G$28 -> 0
A8: BUILT UP
A9: QTY | B9: MARK | C9: DESCRIPTION | G9: DWG # | H9: COLOR | J9: LENGTH | M9: WT.
A11: ="@Data" -> @Data
K39: PAGE WEIGHT: | M39: =SUM(M11:M37) -> 0

Sheet 4
I1: SHIPPER NUMBER | K1: ="@PgNo" -> @PgNo | M1: OF | N1: =Cover!$M$22 -> 10
G2: JOB NUMBER | I2: =Cover!$G$24 -> 403184_Secondary | K2: ISSUE DATE | M2: =Cover!$G$27 -> 45985
G3: BUILDING NUMBER | K3: REVISION NUMBER
G4: DRAWN BY | I4: =Cover!$M$36 | K4: REVISION BY
G5: CHECKED BY | I5: =Cover!$M$37 | K5: REVISION DATE
G6: BLDG DESCRIP. | I6: =Cover!$G$32
A7: CUSTOMER: | C7: =Cover!$G$28 -> 0
A8: HOT ROLLED
A9: QTY | B9: MARK | C9: DESCRIPTION | F9: PART | G9: DWG # | H9: COLOR | J9: LENGTH | M9: WT.
A11: ="@Data" -> @Data
K39: PAGE WEIGHT: | M39: =SUM(M11:M37) -> 0

Sheet 5
I1: SHIPPER NUMBER | K1: ="@PgNo" -> @PgNo | M1: OF | N1: =Cover!$M$22 -> 10
G2: JOB NUMBER | I2: =Cover!$G$24 -> 403184_Secondary | K2: ISSUE DATE | M2: =Cover!$G$27 -> 45985
G3: BUILDING NUMBER | K3: REVISION NUMBER
G4: DRAWN BY | I4: =Cover!$M$36 | K4: REVISION BY
G5: CHECKED BY | I5: =Cover!$M$37 | K5: REVISION DATE
G6: BLDG DESCRIP. | I6: =Cover!$G$32
A7: CUSTOMER: | C7: =Cover!$G$28 -> 0
A8: MISCELLANEOUS HOT ROLLED
A9: QTY | B9: MARK | C9: DESCRIPTION | F9: PART | G9: DWG # | H9: COLOR | J9: LENGTH | M9: WT.
A11: ="@Data" -> @Data
K39: PAGE WEIGHT: | M39: =SUM(M11:M37) -> 0

Sheet 6
I1: SHIPPER NUMBER | K1: ="@PgNo" -> @PgNo | M1: OF | N1: =Cover!$M$22 -> 10
G2: JOB NUMBER | I2: =Cover!$G$24 -> 403184_Secondary | K2: ISSUE DATE | M2: =Cover!$G$27 -> 45985
G3: BUILDING NUMBER | K3: REVISION NUMBER
G4: DRAWN BY | I4: =Cover!$M$36 | K4: REVISION BY
G5: CHECKED BY | I5: =Cover!$M$37 | K5: REVISION DATE
G6: BLDG DESCRIP. | I6: =Cover!$G$32
A7: CUSTOMER: | C7: =Cover!$G$28 -> 0
A8: FABRICATED COLD FORM
A9: QTY | B9: MARK | C9: DESCRIPTION | F9: PART | G9: DWG # | H9: COLOR | J9: LENGTH | M9: WT.
A11: ="@Data" -> @Data
K39: PAGE WEIGHT: | M39: =SUM(M11:M37) -> 0

Sheet 7
I1: SHIPPER NUMBER | K1: ="@PgNo" -> @PgNo | M1: OF | N1: =Cover!$M$22 -> 10
G2: JOB NUMBER | I2: =Cover!$G$24 -> 403184_Secondary | K2: ISSUE DATE | M2: =Cover!$G$27 -> 45985
G3: BUILDING NUMBER | K3: REVISION NUMBER
G4: DRAWN BY | I4: =Cover!$M$36 | K4: REVISION BY
G5: CHECKED BY | I5: =Cover!$M$37 | K5: REVISION DATE
G6: BLDG DESCRIP. | I6: =Cover!$G$32
A7: CUSTOMER: | C7: =Cover!$G$28 -> 0
A8: PRE-GALVANIZED FABRICATED COLD FORM
A9: QTY | B9: MARK | C9: DESCRIPTION | F9: PART | G9: DWG # | H9: COLOR | J9: LENGTH | M9: WT.
A11: ="@Data" -> @Data
K39: PAGE WEIGHT: | M39: =SUM(M11:M37) -> 0

Sheet 8
I1: SHIPPER NUMBER | K1: ="@PgNo" -> @PgNo | M1: OF | N1: =Cover!$M$22 -> 10
G2: JOB NUMBER | I2: =Cover!$G$24 -> 403184_Secondary | K2: ISSUE DATE | M2: =Cover!$G$27 -> 45985
G3: BUILDING NUMBER | K3: REVISION NUMBER
G4: DRAWN BY | I4: =Cover!$M$36 | K4: REVISION BY
G5: CHECKED BY | I5: =Cover!$M$37 | K5: REVISION DATE
G6: BLDG DESCRIP. | I6: =Cover!$G$32
A7: CUSTOMER: | C7: =Cover!$G$28 -> 0
A8: EAVE STRUTS
A9: QTY | B9: MARK | C9: DESCRIPTION | E9: PITCH | F9: PART | G9: PUNCH | H9: COLOR | J9: DWG # | K9: LENGTH | M9: WT.
A11: ="@Data" -> @Data
K39: PAGE WEIGHT: | M39: =SUM(M11:M37) -> 0

Sheet 9
I1: SHIPPER NUMBER | K1: ="@PgNo" -> @PgNo | M1: OF | N1: =Cover!$M$22 -> 10
G2: JOB NUMBER | I2: =Cover!$G$24 -> 403184_Secondary | K2: ISSUE DATE | M2: =Cover!$G$27 -> 45985
G3: BUILDING NUMBER | K3: REVISION NUMBER
G4: DRAWN BY | I4: =Cover!$M$36 | K4: REVISION BY
G5: CHECKED BY | I5: =Cover!$M$37 | K5: REVISION DATE
G6: BLDG DESCRIP. | I6: =Cover!$G$32
A7: CUSTOMER: | C7: =Cover!$G$28 -> 0
A8: COLD FORM MEMBERS (CEE)
A9: QTY | B9: MARK | C9: DESCRIPTION | F9: PART | G9: PUNCH | H9: DWG # | I9: COLOR | K9: LENGTH | M9: WT.
A11: ="@Data" -> @Data
K39: PAGE WEIGHT: | M39: =SUM(M11:M37) -> 0

Sheet 10
I1: SHIPPER NUMBER | K1: ="@PgNo" -> @PgNo | M1: OF | N1: =Cover!$M$22 -> 10
G2: JOB NUMBER | I2: =Cover!$G$24 -> 403184_Secondary | K2: ISSUE DATE | M2: =Cover!$G$27 -> 45985
G3: BUILDING NUMBER | K3: REVISION NUMBER
G4: DRAWN BY | I4: =Cover!$M$36 | K4: REVISION BY
G5: CHECKED BY | I5: =Cover!$M$37 | K5: REVISION DATE
G6: BLDG DESCRIP. | I6: =Cover!$G$32
A7: CUSTOMER: | C7: =Cover!$G$28 -> 0
A8: COLD FORM MEMBERS (ZEE)
A9: QTY | B9: MARK | C9: DESCRIPTION | F9: PART | G9: PUNCH | H9: DWG # | I9: COLOR | K9: LENGTH | M9: WT.
A11: ="@Data" -> @Data
K39: PAGE WEIGHT: | M39: =SUM(M11:M37) -> 0

Sheet 11
I1: SHIPPER NUMBER | K1: ="@PgNo" -> @PgNo | M1: OF | N1: =Cover!$M$22 -> 10
G2: JOB NUMBER | I2: =Cover!$G$24 -> 403184_Secondary | K2: ISSUE DATE | M2: =Cover!$G$27 -> 45985
G3: BUILDING NUMBER | K3: REVISION NUMBER
G4: DRAWN BY | I4: =Cover!$M$36 | K4: REVISION BY
G5: CHECKED BY | I5: =Cover!$M$37 | K5: REVISION DATE
G6: BLDG DESCRIP. | I6: =Cover!$G$32
A7: CUSTOMER: | C7: =Cover!$G$28 -> 0
A8: FLANGE BRACES
A9: QTY | B9: MARK | C9: DESCRIPTION | F9: PART | G9: DWG # | H9: COLOR | J9: LENGTH | M9: WT.
A11: ="@Data" -> @Data
K39: PAGE WEIGHT: | M39: =SUM(M11:M37) -> 0

Sheet 12
I1: SHIPPER NUMBER | K1: ="@PgNo" -> @PgNo | M1: OF | N1: =Cover!$M$22 -> 10
G2: JOB NUMBER | I2: =Cover!$G$24 -> 403184_Secondary | K2: ISSUE DATE | M2: =Cover!$G$27 -> 45985
G3: BUILDING NUMBER | K3: REVISION NUMBER
G4: DRAWN BY | I4: =Cover!$M$36 | K4: REVISION BY
G5: CHECKED BY | I5: =Cover!$M$37 | K5: REVISION DATE
G6: BLDG DESCRIP. | I6: =Cover!$G$32
A7: CUSTOMER: | C7: =Cover!$G$28 -> 0
A8: MISCELLANEOUS COLD FORM
A9: QTY | B9: MARK | C9: DESCRIPTION | F9: PART | G9: DWG # | H9: COLOR | J9: LENGTH | M9: WT.
A11: ="@Data" -> @Data
K39: PAGE WEIGHT: | M39: =SUM(M11:M37) -> 0

Sheet 13
I1: SHIPPER NUMBER | K1: ="@PgNo" -> @PgNo | M1: OF | N1: =Cover!$M$22 -> 10
G2: JOB NUMBER | I2: =Cover!$G$24 -> 403184_Secondary | K2: ISSUE DATE | M2: =Cover!$G$27 -> 45985
G3: BUILDING NUMBER | K3: REVISION NUMBER
G4: DRAWN BY | I4: =Cover!$M$36 | K4: REVISION BY
G5: CHECKED BY | I5: =Cover!$M$37 | K5: REVISION DATE
G6: BLDG DESCRIP. | I6: =Cover!$G$32
A7: CUSTOMER: | C7: =Cover!$G$28 -> 0
A8: CLIPS
A9: QTY | B9: MARK | D9: DESCRIPTION | I9: COLOR | K9: DRAWING # | M9: WT.
A11: ="@Data" -> @Data
K39: PAGE WEIGHT: | M39: =SUM(M11:M37) -> 0

Sheet 14
I1: SHIPPER NUMBER | K1: ="@PgNo" -> @PgNo | M1: OF | N1: =Cover!$M$22 -> 10
G2: JOB NUMBER | I2: =Cover!$G$24 -> 403184_Secondary | K2: ISSUE DATE | M2: =Cover!$G$27 -> 45985
G3: BUILDING NUMBER | K3: REVISION NUMBER
G4: DRAWN BY | I4: =Cover!$M$36 | K4: REVISION BY
G5: CHECKED BY | I5: =Cover!$M$37 | K5: REVISION DATE
G6: BLDG DESCRIP. | I6: =Cover!$G$32
A7: CUSTOMER: | C7: =Cover!$G$28 -> 0
A8: PRE-GALVANIZED CLIPS
A9: QTY | B9: MARK | D9: DESCRIPTION | I9: COLOR | K9: DRAWING # | M9: WT.
A11: ="@Data" -> @Data
K39: PAGE WEIGHT: | M39: =SUM(M11:M37) -> 0

Sheet 15
I1: SHIPPER NUMBER | K1: ="@PgNo" -> @PgNo | M1: OF | N1: =Cover!$M$22 -> 10
G2: JOB NUMBER | I2: =Cover!$G$24 -> 403184_Secondary | K2: ISSUE DATE | M2: =Cover!$G$27 -> 45985
G3: BUILDING NUMBER | K3: REVISION NUMBER
G4: DRAWN BY | I4: =Cover!$M$36 | K4: REVISION BY
G5: CHECKED BY | I5: =Cover!$M$37 | K5: REVISION DATE
G6: BLDG DESCRIP. | I6: =Cover!$G$32
A7: CUSTOMER: | C7: =Cover!$G$28 -> 0
A8: SHEETING (ROOF)
A9: QTY | B9: LOCATION | D9: DESCRIPTION | H9: PITCH | I9: COLOR | K9: LENGTH | M9: WT.
A11: ="@Data" -> @Data
K39: PAGE WEIGHT: | M39: =SUM(M11:M37) -> 0

Sheet 16
I1: SHIPPER NUMBER | K1: ="@PgNo" -> @PgNo | M1: OF | N1: =Cover!$M$22 -> 10
G2: JOB NUMBER | I2: =Cover!$G$24 -> 403184_Secondary | K2: ISSUE DATE | M2: =Cover!$G$27 -> 45985
G3: BUILDING NUMBER | K3: REVISION NUMBER
G4: DRAWN BY | I4: =Cover!$M$36 | K4: REVISION BY
G5: CHECKED BY | I5: =Cover!$M$37 | K5: REVISION DATE
G6: BLDG DESCRIP. | I6: =Cover!$G$32
A7: CUSTOMER: | C7: =Cover!$G$28 -> 0
A8: SHEETING (STANDING SEAM ROOF)
A9: QTY | B9: LOCATION | D9: DESCRIPTION | H9: PITCH | I9: COLOR | K9: LENGTH | M9: WT.
A11: ="@Data" -> @Data
K39: PAGE WEIGHT: | M39: =SUM(M11:M37) -> 0

Sheet 17
I1: SHIPPER NUMBER | K1: ="@PgNo" -> @PgNo | M1: OF | N1: =Cover!$M$22 -> 10
G2: JOB NUMBER | I2: =Cover!$G$24 -> 403184_Secondary | K2: ISSUE DATE | M2: =Cover!$G$27 -> 45985
G3: BUILDING NUMBER | K3: REVISION NUMBER
G4: DRAWN BY | I4: =Cover!$M$36 | K4: REVISION BY
G5: CHECKED BY | I5: =Cover!$M$37 | K5: REVISION DATE
G6: BLDG DESCRIP. | I6: =Cover!$G$32
A7: CUSTOMER: | C7: =Cover!$G$28 -> 0
A8: SHEETING (SIDEWALL)
A9: QTY | B9: LOCATION | D9: DESCRIPTION | H9: COLOR | J9: LENGTH | M9: WT.
A11: ="@Data" -> @Data
K39: PAGE WEIGHT: | M39: =SUM(M11:M37) -> 0

Sheet 18
I1: SHIPPER NUMBER | K1: ="@PgNo" -> @PgNo | M1: OF | N1: =Cover!$M$22 -> 10
G2: JOB NUMBER | I2: =Cover!$G$24 -> 403184_Secondary | K2: ISSUE DATE | M2: =Cover!$G$27 -> 45985
G3: BUILDING NUMBER | K3: REVISION NUMBER
G4: DRAWN BY | I4: =Cover!$M$36 | K4: REVISION BY
G5: CHECKED BY | I5: =Cover!$M$37 | K5: REVISION DATE
G6: BLDG DESCRIP. | I6: =Cover!$G$32
A7: CUSTOMER: | C7: =Cover!$G$28 -> 0
A8: SHEETING (ENDWALL)
A9: QTY | B9: LOCATION | D9: DESCRIPTION | H9: COLOR | J9: LENGTH | M9: WT.
A11: ="@Data" -> @Data
K39: PAGE WEIGHT: | M39: =SUM(M11:M37) -> 0

Sheet 19
I1: SHIPPER NUMBER | K1: ="@PgNo" -> @PgNo | M1: OF | N1: =Cover!$M$22 -> 10
G2: JOB NUMBER | I2: =Cover!$G$24 -> 403184_Secondary | K2: ISSUE DATE | M2: =Cover!$G$27 -> 45985
G3: BUILDING NUMBER | K3: REVISION NUMBER
G4: DRAWN BY | I4: =Cover!$M$36 | K4: REVISION BY
G5: CHECKED BY | I5: =Cover!$M$37 | K5: REVISION DATE
G6: BLDG DESCRIP. | I6: =Cover!$G$32
A7: CUSTOMER: | C7: =Cover!$G$28 -> 0
A8: SHEETING (MISC.)
A9: QTY | B9: LOCATION | D9: DESCRIPTION | H9: COLOR | J9: LENGTH | M9: WT.
A11: ="@Data" -> @Data
K39: PAGE WEIGHT: | M39: =SUM(M11:M37) -> 0

Sheet 20
I1: SHIPPER NUMBER | K1: ="@PgNo" -> @PgNo | M1: OF | N1: =Cover!$M$22 -> 10
G2: JOB NUMBER | I2: =Cover!$G$24 -> 403184_Secondary | K2: ISSUE DATE | M2: =Cover!$G$27 -> 45985
G3: BUILDING NUMBER | K3: REVISION NUMBER
G4: DRAWN BY | I4: =Cover!$M$36 | K4: REVISION BY
G5: CHECKED BY | I5: =Cover!$M$37 | K5: REVISION DATE
G6: BLDG DESCRIP. | I6: =Cover!$G$32
A7: CUSTOMER: | C7: =Cover!$G$28 -> 0
A8: TRIM
A9: QTY | B9: MARK | C9: DESCRIPTION | H9: PITCH | I9: GAUGE | J9: DWG | K9: COLOR | M9: LENGTH | N9: WT.
A11: ="@Data" -> @Data
K39: PAGE WEIGHT: | M39: =SUM(M11:M37) -> 0

Sheet 21
I1: SHIPPER NUMBER | K1: ="@PgNo" -> @PgNo | M1: OF | N1: =Cover!$M$22 -> 10
G2: JOB NUMBER | I2: =Cover!$G$24 -> 403184_Secondary | K2: ISSUE DATE | M2: =Cover!$G$27 -> 45985
G3: BUILDING NUMBER | K3: REVISION NUMBER
G4: DRAWN BY | I4: =Cover!$M$36 | K4: REVISION BY
G5: CHECKED BY | I5: =Cover!$M$37 | K5: REVISION DATE
G6: BLDG DESCRIP. | I6: =Cover!$G$32
A7: CUSTOMER: | C7: =Cover!$G$28 -> 0
A8: STANDING SEAM HARDWARE
A9: QTY | B9: MARK | C9: DESCRIPTION | G9: DWG # | H9: COLOR | J9: LENGTH | M9: WT.
A11: ="@Data" -> @Data
K39: PAGE WEIGHT: | M39: =SUM(M11:M37) -> 0

Sheet 22
I1: SHIPPER NUMBER | K1: ="@PgNo" -> @PgNo | M1: OF | N1: =Cover!$M$22 -> 10
G2: JOB NUMBER | I2: =Cover!$G$24 -> 403184_Secondary | K2: ISSUE DATE | M2: =Cover!$G$27 -> 45985
G3: BUILDING NUMBER | K3: REVISION NUMBER
G4: DRAWN BY | I4: =Cover!$M$36 | K4: REVISION BY
G5: CHECKED BY | I5: =Cover!$M$37 | K5: REVISION DATE
G6: BLDG DESCRIP. | I6: =Cover!$G$32
A7: CUSTOMER: | C7: =Cover!$G$28 -> 0
A8: ROD BRACING
A9: QTY | B9: MARK | C9: DESCRIPTION | H9: COLOR | J9: LENGTH | M9: WT.
A11: ="@Data" -> @Data
A36: Rod Bracing Includes (1) Hillside Washer, (1) Flat Washer, & (1) Nut at Each End
K39: PAGE WEIGHT: | M39: =SUM(M11:M37) -> 0

Sheet 23
I1: SHIPPER NUMBER | K1: ="@PgNo" -> @PgNo | M1: OF | N1: =Cover!$M$22 -> 10
G2: JOB NUMBER | I2: =Cover!$G$24 -> 403184_Secondary | K2: ISSUE DATE | M2: =Cover!$G$27 -> 45985
G3: BUILDING NUMBER | K3: REVISION NUMBER
G4: DRAWN BY | I4: =Cover!$M$36 | K4: REVISION BY
G5: CHECKED BY | I5: =Cover!$M$37 | K5: REVISION DATE
G6: BLDG DESCRIP. | I6: =Cover!$G$32
A7: CUSTOMER: | C7: =Cover!$G$28 -> 0
A8: CABLE BRACING
A9: QTY | B9: MARK | D9: DESCRIPTION | J9: LENGTH | M9: WT.
A11: ="@Data" -> @Data
A36: Cable Bracing Includes (1) Eyebolt, (1) Hillside Washer, (1) Flat Washer, & (1) Nut at Each End
K39: PAGE WEIGHT: | M39: =SUM(M11:M37) -> 0

Sheet 24
I1: SHIPPER NUMBER | K1: ="@PgNo" -> @PgNo | M1: OF | N1: =Cover!$M$22 -> 10
G2: JOB NUMBER | I2: =Cover!$G$24 -> 403184_Secondary | K2: ISSUE DATE | M2: =Cover!$G$27 -> 45985
G3: BUILDING NUMBER | K3: REVISION NUMBER
G4: DRAWN BY | I4: =Cover!$M$36 | K4: REVISION BY
G5: CHECKED BY | I5: =Cover!$M$37 | K5: REVISION DATE
G6: BLDG DESCRIP. | I6: =Cover!$G$32
A7: CUSTOMER: | C7: =Cover!$G$28 -> 0
A8: MASTICS
A9: QTY | B9: MARK | C9: DESCRIPTION | H9: COLOR | J9: LENGTH | M9: WT.
A11: ="@Data" -> @Data
K39: PAGE WEIGHT: | M39: =SUM(M11:M37) -> 0

Sheet 25
I1: SHIPPER NUMBER | K1: ="@PgNo" -> @PgNo | M1: OF | N1: =Cover!$M$22 -> 10
G2: JOB NUMBER | I2: =Cover!$G$24 -> 403184_Secondary | K2: ISSUE DATE | M2: =Cover!$G$27 -> 45985
G3: BUILDING NUMBER | K3: REVISION NUMBER
G4: DRAWN BY | I4: =Cover!$M$36 | K4: REVISION BY
G5: CHECKED BY | I5: =Cover!$M$37 | K5: REVISION DATE
G6: BLDG DESCRIP. | I6: =Cover!$G$32
A7: CUSTOMER: | C7: =Cover!$G$28 -> 0
A8: BOLTS
A9: QTY | B9: MARK | C9: DESCRIPTION | H9: COLOR | J9: LENGTH | M9: WT.
A11: ="@Data" -> @Data
K39: PAGE WEIGHT: | M39: =SUM(M11:M37) -> 0

Sheet 26
I1: SHIPPER NUMBER | K1: ="@PgNo" -> @PgNo | M1: OF | N1: =Cover!$M$22 -> 10
G2: JOB NUMBER | I2: =Cover!$G$24 -> 403184_Secondary | K2: ISSUE DATE | M2: =Cover!$G$27 -> 45985
G3: BUILDING NUMBER | K3: REVISION NUMBER
G4: DRAWN BY | I4: =Cover!$M$36 | K4: REVISION BY
G5: CHECKED BY | I5: =Cover!$M$37 | K5: REVISION DATE
G6: BLDG DESCRIP. | I6: =Cover!$G$32
A7: CUSTOMER: | C7: =Cover!$G$28 -> 0
A8: SCREWS
A9: QTY | B9: MARK | C9: DESCRIPTION | H9: COLOR | J9: LENGTH | M9: WT.
A11: ="@Data" -> @Data
K39: PAGE WEIGHT: | M39: =SUM(M11:M37) -> 0

Sheet 27
I1: SHIPPER NUMBER | K1: ="@PgNo" -> @PgNo | M1: OF | N1: =Cover!$M$22 -> 10
G2: JOB NUMBER | I2: =Cover!$G$24 -> 403184_Secondary | K2: ISSUE DATE | M2: =Cover!$G$27 -> 45985
G3: BUILDING NUMBER | K3: REVISION NUMBER
G4: DRAWN BY | I4: =Cover!$M$36 | K4: REVISION BY
G5: CHECKED BY | I5: =Cover!$M$37 | K5: REVISION DATE
G6: BLDG DESCRIP. | I6: =Cover!$G$32
A7: CUSTOMER: | C7: =Cover!$G$28 -> 0
A8: WALKDOORS
A9: QTY | B9: TYPE | E9: WIND RATING | F9: SWING | H9: LEAF | I9: LOCK TYPE | L9: CLOSER TYPE | M9: COLOR | N9: FRAME
A11: ="@Walk" -> @Walk

Sheet 28
I1: SHIPPER NUMBER | K1: ="@PgNo" -> @PgNo | M1: OF | N1: =Cover!$M$22 -> 10
G2: JOB NUMBER | I2: =Cover!$G$24 -> 403184_Secondary | K2: ISSUE DATE | M2: =Cover!$G$27 -> 45985
G3: BUILDING NUMBER | K3: REVISION NUMBER
G4: DRAWN BY | I4: =Cover!$M$36 | K4: REVISION BY
G5: CHECKED BY | I5: =Cover!$M$37 | K5: REVISION DATE
G6: BLDG DESCRIP. | I6: =Cover!$G$32
A7: CUSTOMER: | C7: =Cover!$G$28 -> 0
A8: WINDOWS
A9: QTY | B9: MARK | C9: DESCRIPTION | H9: GLASS | J9: FRAME COLOR | L9: FIN TYPE | M9: FIN TRIM
A11: ="@Data" -> @Data

Sheet 29
I1: SHIPPER NUMBER | K1: ="@PgNo" -> @PgNo | M1: OF | N1: =Cover!$M$22 -> 10
G2: JOB NUMBER | I2: =Cover!$G$24 -> 403184_Secondary | K2: ISSUE DATE | M2: =Cover!$G$27 -> 45985
G3: BUILDING NUMBER | K3: REVISION NUMBER
G4: DRAWN BY | I4: =Cover!$M$36 | K4: REVISION BY
G5: CHECKED BY | I5: =Cover!$M$37 | K5: REVISION DATE
G6: BLDG DESCRIP. | I6: =Cover!$G$32
A7: CUSTOMER: | C7: =Cover!$G$28 -> 0
A8: CONTINUOUS RIDGE VENTS
A9: QTY | B9: DESCRIPTION | F9: PITCH | G9: COLOR | I9: FINS | J9: OPERATOR W/(2) CLAMPS, (2) PULLEYS (PER VENT)
J10: 3/16" DIA. CABLE | L10: EYEBOLT w/NUTS | N10: HANDLE
A12: ="@Data" -> @Data

Sheet 30
I1: SHIPPER NUMBER | K1: ="@PgNo" -> @PgNo | M1: OF | N1: =Cover!$M$22 -> 10
G2: JOB NUMBER | I2: =Cover!$G$24 -> 403184_Secondary | K2: ISSUE DATE | M2: =Cover!$G$27 -> 45985
G3: BUILDING NUMBER | K3: REVISION NUMBER
G4: DRAWN BY | I4: =Cover!$M$36 | K4: REVISION BY
G5: CHECKED BY | I5: =Cover!$M$37 | K5: REVISION DATE
G6: BLDG DESCRIP. | I6: =Cover!$G$32
A7: CUSTOMER: | C7: =Cover!$G$28 -> 0
A8: ROUND VENTS
A9: QTY | B9: DESCRIPTION | F9: PITCH | G9: COLOR | I9: BASE | J9: OPERATOR W/(2) CLAMPS, (2) PULLEYS (PER VENT)
J10: 3/16" DIA. CABLE | L10: EYEBOLT w/NUTS | N10: HANDLE
A12: ="@Data" -> @Data

Sheet 31
I1: SHIPPER NUMBER | K1: ="@PgNo" -> @PgNo | M1: OF | N1: =Cover!$M$22 -> 10
G2: JOB NUMBER | I2: =Cover!$G$24 -> 403184_Secondary | K2: ISSUE DATE | M2: =Cover!$G$27 -> 45985
G3: BUILDING NUMBER | K3: REVISION NUMBER
G4: DRAWN BY | I4: =Cover!$M$36 | K4: REVISION BY
G5: CHECKED BY | I5: =Cover!$M$37 | K5: REVISION DATE
G6: BLDG DESCRIP. | I6: =Cover!$G$32
A7: CUSTOMER: | C7: =Cover!$G$28 -> 0
A8: LOUVERS
A9: QTY | B9: DESCRIPTION | G9: SCREEN | I9: FIN TYPE | K9: SILL HEIGHT | M9: COLOR
A11: ="@Data" -> @Data

Sheet 32
I1: SHIPPER NUMBER | K1: ="@PgNo" -> @PgNo | M1: OF | N1: =Cover!$M$22 -> 10
G2: JOB NUMBER | I2: =Cover!$G$24 -> 403184_Secondary | K2: ISSUE DATE | M2: =Cover!$G$27 -> 45985
G3: BUILDING NUMBER | K3: REVISION NUMBER
G4: DRAWN BY | I4: =Cover!$M$36 | K4: REVISION BY
G5: CHECKED BY | I5: =Cover!$M$37 | K5: REVISION DATE
G6: BLDG DESCRIP. | I6: =Cover!$G$32
A7: CUSTOMER: | C7: =Cover!$G$28 -> 0
A8: MISCELLANEOUS ACCESSORIES
A9: QTY | B9: MARK | D9: DESCRIPTION | K9: COLOR | M9: WT.
A11: ="@Data" -> @Data

Sheet 35
I1: SHIPPER NUMBER | K1: ="@PgNo" -> @PgNo | M1: OF | N1: =Cover!$M$22 -> 10
G2: JOB NUMBER | I2: =Cover!$G$24 -> 403184_Secondary | K2: ISSUE DATE | M2: =Cover!$G$27 -> 45985
G3: BUILDING NUMBER | K3: REVISION NUMBER
G4: DRAWN BY | I4: =Cover!$M$36 | K4: REVISION BY
G5: CHECKED BY | I5: =Cover!$M$37 | K5: REVISION DATE
G6: BLDG DESCRIP. | I6: =Cover!$G$32
A7: CUSTOMER: | C7: =Cover!$G$28 -> 0
A8: STANDING SEAM SKYLIGHTS
A9: QTY | B9: MARK | C9: DESCRIPTION | G9: COLOR | I9: WINDOW | K9: LENGTH | M9: WT.
A11: ="@Data" -> @Data
K39: PAGE WEIGHT: | M39: =SUM(M11:M37) -> 0
